Traceback (most recent call last):
  File "/disk/disk3/gyeongmin/bess_arbitrage/parallel_monthly.py", line 166, in <module>
    main()
  File "/disk/disk3/gyeongmin/bess_arbitrage/parallel_monthly.py", line 158, in main
    net_arbitrage_revenues_per_config = list(
                                        ^^^^^
  File "/disk/disk3/gyeongmin/miniconda3/lib/python3.12/concurrent/futures/process.py", line 642, in _chain_from_iterable_of_lists
    for element in iterable:
  File "/disk/disk3/gyeongmin/miniconda3/lib/python3.12/concurrent/futures/_base.py", line 619, in result_iterator
    yield _result_or_cancel(fs.pop())
          ^^^^^^^^^^^^^^^^^^^^^^^^^^^
  File "/disk/disk3/gyeongmin/miniconda3/lib/python3.12/concurrent/futures/_base.py", line 317, in _result_or_cancel
    return fut.result(timeout)
           ^^^^^^^^^^^^^^^^^^^
  File "/disk/disk3/gyeongmin/miniconda3/lib/python3.12/concurrent/futures/_base.py", line 456, in result
    return self.__get_result()
           ^^^^^^^^^^^^^^^^^^^
  File "/disk/disk3/gyeongmin/miniconda3/lib/python3.12/concurrent/futures/_base.py", line 401, in __get_result
    raise self._exception
concurrent.futures.process.BrokenProcessPool: A process in the process pool was terminated abruptly while the future was running or pending.
Traceback (most recent call last):
  File "/disk/disk3/gyeongmin/bess_arbitrage/parallel_monthly.py", line 166, in <module>
    main()
  File "/disk/disk3/gyeongmin/bess_arbitrage/parallel_monthly.py", line 158, in main
    net_arbitrage_revenues_per_config = list(
                                        ^^^^^
  File "/disk/disk3/gyeongmin/miniconda3/lib/python3.12/concurrent/futures/process.py", line 642, in _chain_from_iterable_of_lists
    for element in iterable:
  File "/disk/disk3/gyeongmin/miniconda3/lib/python3.12/concurrent/futures/_base.py", line 619, in result_iterator
    yield _result_or_cancel(fs.pop())
          ^^^^^^^^^^^^^^^^^^^^^^^^^^^
  File "/disk/disk3/gyeongmin/miniconda3/lib/python3.12/concurrent/futures/_base.py", line 317, in _result_or_cancel
    return fut.result(timeout)
           ^^^^^^^^^^^^^^^^^^^
  File "/disk/disk3/gyeongmin/miniconda3/lib/python3.12/concurrent/futures/_base.py", line 456, in result
    return self.__get_result()
           ^^^^^^^^^^^^^^^^^^^
  File "/disk/disk3/gyeongmin/miniconda3/lib/python3.12/concurrent/futures/_base.py", line 401, in __get_result
    raise self._exception
concurrent.futures.process.BrokenProcessPool: A process in the process pool was terminated abruptly while the future was running or pending.
